{"trial_id": "00", "hyperparameters": {"space": [{"class_name": "Choice", "config": {"name": "units", "default": 8, "conditions": [], "values": [8, 16, 32, 64, 128], "ordered": true}}, {"class_name": "Choice", "config": {"name": "dropout", "default": 0.2, "conditions": [], "values": [0.2, 0.3, 0.4], "ordered": true}}, {"class_name": "Choice", "config": {"name": "optimizer", "default": "SGD", "conditions": [], "values": ["SGD", "Adam", "RMSprop"], "ordered": false}}, {"class_name": "Choice", "config": {"name": "sgd_lr", "default": 0.01, "conditions": [], "values": [0.01, 0.005, 0.001, 0.0005], "ordered": true}}], "values": {"units": 16, "dropout": 0.2, "optimizer": "SGD", "sgd_lr": 0.005}}, "metrics": {"metrics": {}}, "score": null, "best_step": 0, "status": "FAILED", "message": "Traceback (most recent call last):\n  File \"c:\\Users\\Dell\\Desktop\\MP\\myenv\\lib\\site-packages\\keras_tuner\\src\\engine\\base_tuner.py\", line 274, in _try_run_and_update_trial\n    self._run_and_update_trial(trial, *fit_args, **fit_kwargs)\n  File \"c:\\Users\\Dell\\Desktop\\MP\\myenv\\lib\\site-packages\\keras_tuner\\src\\engine\\base_tuner.py\", line 239, in _run_and_update_trial\n    results = self.run_trial(trial, *fit_args, **fit_kwargs)\n  File \"c:\\Users\\Dell\\Desktop\\MP\\myenv\\lib\\site-packages\\keras_tuner\\src\\engine\\tuner.py\", line 314, in run_trial\n    obj_value = self._build_and_fit_model(trial, *args, **copied_kwargs)\n  File \"c:\\Users\\Dell\\Desktop\\MP\\myenv\\lib\\site-packages\\keras_tuner\\src\\engine\\tuner.py\", line 233, in _build_and_fit_model\n    results = self.hypermodel.fit(hp, model, *args, **kwargs)\n  File \"c:\\Users\\Dell\\Desktop\\MP\\myenv\\lib\\site-packages\\keras_tuner\\src\\engine\\hypermodel.py\", line 149, in fit\n    return model.fit(*args, **kwargs)\n  File \"c:\\Users\\Dell\\Desktop\\MP\\myenv\\lib\\site-packages\\keras\\src\\utils\\traceback_utils.py\", line 70, in error_handler\n    raise e.with_traceback(filtered_tb) from None\n  File \"c:\\Users\\Dell\\Desktop\\MP\\myenv\\lib\\site-packages\\keras\\src\\engine\\data_adapter.py\", line 1950, in _check_data_cardinality\n    raise ValueError(msg)\nValueError: Data cardinality is ambiguous:\n  x sizes: 7566\n  y sizes: 800\nMake sure all arrays contain the same number of samples.\n"}